<?xml version="1.0" encoding="UTF-8"?>
<!-- Generated by org.testng.reporters.JUnitReportReporter -->
<testsuite skipped="2" hostname="LP0039" name="com.qa.tests.TestNGDemoTest" tests="8" failures="1" timestamp="10 Mar 2018 17:49:12 GMT" time="0.059" errors="0">
  <testcase name="test1" time="0.016" classname="com.qa.tests.TestNGDemoTest"/>
  <testcase name="test4" time="0.000" classname="com.qa.tests.TestNGDemoTest">
    <skipped/>
  </testcase> <!-- test4 -->
  <testcase name="test2" time="0.016" classname="com.qa.tests.TestNGDemoTest">
    <failure type="java.lang.AssertionError" message="expected [true] but found [false]">
      <![CDATA[java.lang.AssertionError: expected [true] but found [false]
at org.testng.Assert.fail(Assert.java:96)
at org.testng.Assert.failNotEquals(Assert.java:776)
at org.testng.Assert.assertTrue(Assert.java:44)
at org.testng.Assert.assertTrue(Assert.java:54)
at com.qa.tests.TestNGDemoTest.test2(TestNGDemoTest.java:28)
at sun.reflect.NativeMethodAccessorImpl.invoke0(Native Method)
at sun.reflect.NativeMethodAccessorImpl.invoke(NativeMethodAccessorImpl.java:62)
at sun.reflect.DelegatingMethodAccessorImpl.invoke(DelegatingMethodAccessorImpl.java:43)
at java.lang.reflect.Method.invoke(Method.java:498)
at org.testng.internal.MethodInvocationHelper.invokeMethod(MethodInvocationHelper.java:124)
at org.testng.internal.Invoker.invokeMethod(Invoker.java:580)
at org.testng.internal.Invoker.invokeTestMethod(Invoker.java:716)
at org.testng.internal.Invoker.invokeTestMethods(Invoker.java:988)
at org.testng.internal.TestMethodWorker.invokeTestMethods(TestMethodWorker.java:125)
at org.testng.internal.TestMethodWorker.run(TestMethodWorker.java:109)
at org.testng.TestRunner.privateRun(TestRunner.java:648)
at org.testng.TestRunner.run(TestRunner.java:505)
at org.testng.SuiteRunner.runTest(SuiteRunner.java:455)
at org.testng.SuiteRunner.access$000(SuiteRunner.java:40)
at org.testng.SuiteRunner$SuiteWorker.run(SuiteRunner.java:489)
at org.testng.internal.thread.ThreadUtil$1.call(ThreadUtil.java:52)
at java.util.concurrent.FutureTask.run(FutureTask.java:266)
at java.util.concurrent.ThreadPoolExecutor.runWorker(ThreadPoolExecutor.java:1149)
at java.util.concurrent.ThreadPoolExecutor$Worker.run(ThreadPoolExecutor.java:624)
at java.lang.Thread.run(Thread.java:748)
]]>
    </failure>
  </testcase> <!-- test2 -->
  <testcase name="test6" time="0.011" classname="com.qa.tests.TestNGDemoTest"/>
  <testcase name="test6" time="0.010" classname="com.qa.tests.TestNGDemoTest"/>
  <testcase name="test6" time="0.004" classname="com.qa.tests.TestNGDemoTest"/>
  <testcase name="test5" time="0.002" classname="com.qa.tests.TestNGDemoTest"/>
  <testcase name="test3" classname="com.qa.tests.TestNGDemoTest">
    <skipped/>
  </testcase> <!-- test3 -->
</testsuite> <!-- com.qa.tests.TestNGDemoTest -->
